<?xml version="1.0"?>
<robot xmlns:xacro="http://www.ros.org/wiki/xacro">
  <xacro:macro name="autolife_right_arm" params="prefix parent">
<link name="${prefix}Link_Right_Shoulder_Inner_to_Shoulder_Outer">
      <inertial>
        <origin xyz="0.0020083 0.00084722 0.043929" rpy="0 0 0" />
        <mass value="0.38513" />
        <inertia ixx="0.000633" ixy="-1.1E-06" ixz="1.62E-05" iyy="0.001" iyz="-4E-06" izz="0.000699" />
      </inertial>
      <visual>
        <origin xyz="0 0 0" rpy="0 0 0" />
        <geometry>
          <mesh filename="package://autolife_description/meshes/autolife/Link_Right_Shoulder_Inner_to_Shoulder_Outer.STL" />
        </geometry>
        <material name="">
          <color rgba="0.79216 0.81961 0.93333 1" />
        </material>
      </visual>
      <collision>
        <origin xyz="0 0 0" rpy="0 0 0" />
        <geometry>
          <mesh filename="package://autolife_description/meshes/autolife/Link_Right_Shoulder_Inner_to_Shoulder_Outer.STL" />
        </geometry>
      </collision>
    </link>
  
<joint name="${prefix}Joint_Right_Shoulder_Inner" type="revolute">
      <origin xyz="0 0.1426 -0.27507" rpy="-1.5708 0 0" />
      <parent link="${parent}" />
      <child link="${prefix}Link_Right_Shoulder_Inner_to_Shoulder_Outer" />
      <axis xyz="0 0 1" />
      <limit lower="-2.932" upper="2.932" effort="97" velocity="4.1887911" />
    </joint>
  
<link name="${prefix}Link_Right_Shoulder_Outer_to_UpperArm">
      <inertial>
        <origin xyz="0.055229 -0.0026942 -0.035513" rpy="0 0 0" />
        <mass value="1.81394" />
        <inertia ixx="0.001495" ixy="-0.0002" ixz="0.00019" iyy="0.005679" iyz="5.89E-06" izz="0.00585" />
      </inertial>
      <visual>
        <origin xyz="0 0 0" rpy="0 0 0" />
        <geometry>
          <mesh filename="package://autolife_description/meshes/autolife/Link_Right_Shoulder_Outer_to_UpperArm.STL" />
        </geometry>
        <material name="">
          <color rgba="0.79216 0.81961 0.93333 1" />
        </material>
      </visual>
      <collision>
        <origin xyz="0 0 0" rpy="0 0 0" />
        <geometry>
          <mesh filename="package://autolife_description/meshes/autolife/Link_Right_Shoulder_Outer_to_UpperArm.STL" />
        </geometry>
      </collision>
    </link>
  
<joint name="${prefix}Joint_Right_Shoulder_Outer" type="revolute">
      <origin xyz="0.036 0 0.081" rpy="-1.5708 0 -1.5708" />
      <parent link="${prefix}Link_Right_Shoulder_Inner_to_Shoulder_Outer" />
      <child link="${prefix}Link_Right_Shoulder_Outer_to_UpperArm" />
      <axis xyz="0 0 -1" />
      <limit lower="-0.3141" upper="3.1415" effort="97" velocity="4.1887911" />
    </joint>
  
<link name="${prefix}Link_Right_UpperArm_to_Elbow">
      <inertial>
        <origin xyz="0.010425 -0.0018943 0.14817" rpy="0 0 0" />
        <mass value="1.16452" />
        <inertia ixx="0.005555" ixy="-4.6E-05" ixz="0.000755" iyy="0.005834" iyz="-0.00018" izz="0.001025" />
      </inertial>
      <visual>
        <origin xyz="0 0 0" rpy="0 0 0" />
        <geometry>
          <mesh filename="package://autolife_description/meshes/autolife/Link_Right_UpperArm_to_Elbow.STL" />
        </geometry>
        <material name="">
          <color rgba="0.79216 0.81961 0.93333 1" />
        </material>
      </visual>
      <collision>
        <origin xyz="0 0 0" rpy="0 0 0" />
        <geometry>
          <mesh filename="package://autolife_description/meshes/autolife/Link_Right_UpperArm_to_Elbow.STL" />
        </geometry>
      </collision>
    </link>
  
<joint name="${prefix}Joint_Right_UpperArm" type="revolute">
      <origin xyz="0.12925 -0.0045 -0.036" rpy="1.5708 -1.5708 1.5708" />
      <parent link="${prefix}Link_Right_Shoulder_Outer_to_UpperArm" />
      <child link="${prefix}Link_Right_UpperArm_to_Elbow" />
      <axis xyz="0 0 1" />
      <limit lower="-2.915" upper="2.915" effort="97" velocity="4.1887911" />
    </joint>
  
<link name="${prefix}Link_Right_Elbow_to_Forearm">
      <inertial>
        <origin xyz="0.07444 0.023652 -0.033684" rpy="0 0 0" />
        <mass value="0.71152" />
        <inertia ixx="0.000627" ixy="7.91E-05" ixz="-0.00013" iyy="0.001365" iyz="-2E-05" izz="0.001303" />
      </inertial>
      <visual>
        <origin xyz="0 0 0" rpy="0 0 0" />
        <geometry>
          <mesh filename="package://autolife_description/meshes/autolife/Link_Right_Elbow_to_Forearm.STL" />
        </geometry>
        <material name="">
          <color rgba="0.79216 0.81961 0.93333 1" />
        </material>
      </visual>
      <collision>
        <origin xyz="0 0 0" rpy="0 0 0" />
        <geometry>
          <mesh filename="package://autolife_description/meshes/autolife/Link_Right_Elbow_to_Forearm.STL" />
        </geometry>
      </collision>
    </link>
  
<joint name="${prefix}Joint_Right_Elbow" type="revolute">
      <origin xyz="0.025 -0.036125 0.20735" rpy="0 -1.5708 1.5708" />
      <parent link="${prefix}Link_Right_UpperArm_to_Elbow" />
      <child link="${prefix}Link_Right_Elbow_to_Forearm" />
      <axis xyz="0 0 1" />
      <limit lower="-2.618" upper="0" effort="97" velocity="4.1887911" />
    </joint>
  
<link name="${prefix}Link_Right_Forearm_to_Wrist_Upper">
      <inertial>
        <origin xyz="0.0087568 -2.1884E-07 0.025031" rpy="0 0 0" />
        <mass value="0.17972" />
        <inertia ixx="0.000152" ixy="3.5E-09" ixz="3.29E-05" iyy="0.000257" iyz="1.77E-09" izz="0.000226" />
      </inertial>
      <visual>
        <origin xyz="0 0 0" rpy="0 0 0" />
        <geometry>
          <mesh filename="package://autolife_description/meshes/autolife/Link_Right_Forearm_to_Wrist_Upper.STL" />
        </geometry>
        <material name="">
          <color rgba="0.79216 0.81961 0.93333 1" />
        </material>
      </visual>
      <collision>
        <origin xyz="0 0 0" rpy="0 0 0" />
        <geometry>
          <mesh filename="package://autolife_description/meshes/autolife/Link_Right_Forearm_to_Wrist_Upper.STL" />
        </geometry>
      </collision>
    </link>
  
<joint name="${prefix}Joint_Right_Forearm" type="revolute">
      <origin xyz="0.13095 0.025 -0.036125" rpy="-1.5708 0 -1.5708" />
      <parent link="${prefix}Link_Right_Elbow_to_Forearm" />
      <child link="${prefix}Link_Right_Forearm_to_Wrist_Upper" />
      <axis xyz="0 0 1" />
      <limit lower="-2.9496" upper="2.9496" effort="27" velocity="3.76991111" />
    </joint>
  
<link name="${prefix}Link_Right_Wrist_Upper_to_Wrist_Lower">
      <inertial>
        <origin xyz="0.027702 0.002532 -0.031165" rpy="0 0 0" />
        <mass value="0.89687" />
        <inertia ixx="0.000504" ixy="5.8E-05" ixz="-6.2E-05" iyy="0.00125" iyz="9.34E-06" izz="0.001249" />
      </inertial>
      <visual>
        <origin xyz="0 0 0" rpy="0 0 0" />
        <geometry>
          <mesh filename="package://autolife_description/meshes/autolife/Link_Right_Wrist_Upper_to_Wrist_Lower.STL" />
        </geometry>
        <material name="">
          <color rgba="0.79216 0.81961 0.93333 1" />
        </material>
      </visual>
      <collision>
        <origin xyz="0 0 0" rpy="0 0 0" />
        <geometry>
          <mesh filename="package://autolife_description/meshes/autolife/Link_Right_Wrist_Upper_to_Wrist_Lower.STL" />
        </geometry>
      </collision>
    </link>
  
<joint name="${prefix}Joint_Right_Wrist_Upper" type="revolute">
      <origin xyz="0.03035 0 0.05335" rpy="0 -1.5708 3.1416" />
      <parent link="${prefix}Link_Right_Forearm_to_Wrist_Upper" />
      <child link="${prefix}Link_Right_Wrist_Upper_to_Wrist_Lower" />
      <axis xyz="0 0 -1" />
      <limit lower="-1.396" upper="1.396" effort="27" velocity="3.76991111" />
    </joint>
  
<link name="${prefix}Link_Right_Wrist_Lower_to_Gripper">
      <inertial>
        <origin xyz="0.075472 -4.128E-05 -0.027694" rpy="0 0 0" />
        <mass value="0.65144" />
        <inertia ixx="0.000433" ixy="8.4E-09" ixz="-0.00012" iyy="0.000967" iyz="8.56E-08" izz="0.000813" />
      </inertial>
      <visual>
        <origin xyz="0 0 0" rpy="0 0 0" />
        <geometry>
          <mesh filename="package://autolife_description/meshes/autolife/Link_Right_Wrist_Lower_to_Gripper.STL" />
        </geometry>
        <material name="">
          <color rgba="0.79216 0.81961 0.93333 1" />
        </material>
      </visual>
      <collision>
        <origin xyz="0 0 0" rpy="0 0 0" />
        <geometry>
          <mesh filename="package://autolife_description/meshes/autolife/Link_Right_Wrist_Lower_to_Gripper.STL" />
        </geometry>
      </collision>
    </link>
  
<joint name="${prefix}Joint_Right_Wrist_Lower" type="revolute">
      <origin xyz="0.0592 0.03035 -0.03035" rpy="-1.5708 0 0" />
      <parent link="${prefix}Link_Right_Wrist_Upper_to_Wrist_Lower" />
      <child link="${prefix}Link_Right_Wrist_Lower_to_Gripper" />
      <axis xyz="0 0 1" />
      <limit lower="-1.4486" upper="1.4486" effort="27" velocity="3.76991111" />
    </joint>
  
  </xacro:macro>
</robot>
